	public class ProgramaException{
		private int variavel;
		public static void main(String [] args){
			//testeException1();
			//testeException2();	
			testeException3();
		}
		public static void testeException1(){
			int [] vetor1 = new int [5];
			System.out.println("Teste Exception 1 ");
			try{
				vetor1 [6] = 10;
				System.out.println("Teste Exception 1 - Ap贸s o erro");
			}

			catch(Exception e){
				System.out.println("Um erro ocorreu. E ester erro foi:");
				e.printStackTrace();
			}
		}
		
		public static void testeException2(){
			int [] vetor1 = new int [5];
			System.out.println("Teste Exception 2 ");
			try{
				vetor1 [6] = 10;
				System.out.println("Teste Exception 2 - Ap贸s o erro");
			}

			catch(ArrayIndexOutOfBoundsException e){
				System.out.println("Um erro ocorreu. E ester erro foi:");
				}
		}
	public static void testeException3(){
			int [] vetor1 = new int [5];
			System.out.println("Teste Exception 3 ");
			try{
				vetor1 [6] = 10;
				System.out.println("Teste Exception 3 - Ap贸s o erro");
			}

			catch(NullPointerException e){
				System.out.println("Um erro ocorreu. E ester erro foi:");
				
			}
			finally{
				System.out.println("Teste Exception 3 - ap贸s catch");
			}
		}
	}
